Workbook

Sheet Table 1
B2: Notes de tall 1a assignació Juny 2025 (11/07/25)
B3: Ordre alfabètic per centre d'estudi
B4: ESTUDIS DE GRAU I TÍTOLS PROPIS
B5: Code | C5: Degree | D5: University | E5: Location | F5: Province | G5: Field | H5: High-School Specialization | I5: PAU | J5: >25 Years Old | K5: Degree Holders | L5: >45 Years Old
B6: 41035 | C6: Administració d'Empreses i Gestió de la Innovació / Turisme i Gestió del Lleure "Tecnocampus" (simultaneïtat) (Mataró) | D6: UPF | E6: Mataró | F6: =+_xlfn.XLOOKUP(E6,Data_Cleaning!$B$6:$B$50,Data_Cleaning!$C$6:$C$50) -> Barcelona​ | G6: {=_xlfn.XLOOKUP(TRUE,ISNUMBER(SEARCH(Data_Cleaning!$F$6:$F$36,C6)),Data_Cleaning!$G$6:$G$36,"Other",0)} -> Double Degree | H6: Social Sciences | I6: 5000 | J6: 5000 | K6: 5000 | L6: 5000
B7: 71063 | C7: Administració i Direcció d'Empreses "IGEMA" (Barcelona) | D7: URV | E7: Barcelona | F7: =+_xlfn.XLOOKUP(E7,Data_Cleaning!$B$6:$B$50,Data_Cleaning!$C$6:$C$50) -> Barcelona​ | G7: {=_xlfn.XLOOKUP(TRUE,ISNUMBER(SEARCH(Data_Cleaning!$F$6:$F$36,C7)),Data_Cleaning!$G$6:$G$36,"Other",0)} -> Social Sciences and Law | H7: =+_xlfn.XLOOKUP(G7,Data_Cleaning!$J$6:$J$11,Data_Cleaning!$K$6:$K$11) -> Social Sciences | I7: 5000 | J7: 5000 | K7: 5000 | L7: 5000
B8: 61077 | C8: Administració i Direcció d'Empreses i Transformació de Negocis "Centre Universitari EAE" (Barcelona) | D8: UdL | E8: Barcelona | F8: =+_xlfn.XLOOKUP(E8,Data_Cleaning!$B$6:$B$50,Data_Cleaning!$C$6:$C$50) -> Barcelona​ | G8: {=_xlfn.XLOOKUP(TRUE,ISNUMBER(SEARCH(Data_Cleaning!$F$6:$F$36,C8)),Data_Cleaning!$G$6:$G$36,"Other",0)} -> Social Sciences and Law | H8: =+_xlfn.XLOOKUP(G8,Data_Cleaning!$J$6:$J$11,Data_Cleaning!$K$6:$K$11) -> Social Sciences | I8: 5000 | J8: 5000 | K8: 5000 | L8: 5000
B9: 71049 | C9: Antropologia i Evolució Humana (virtual o semipresencial) (Tarragona) | D9: URV / UOC | E9: Tarragona | F9: =+_xlfn.XLOOKUP(E9,Data_Cleaning!$B$6:$B$50,Data_Cleaning!$C$6:$C$50) -> Tarragona​ | G9: Social Sciences and Law | H9: =+_xlfn.XLOOKUP(G9,Data_Cleaning!$J$6:$J$11,Data_Cleaning!$K$6:$K$11) -> Social Sciences | I9: 5000 | J9: 5000 | K9: 5000 | L9: 5000
B10: 21152 | C10: Antropologia Social i Cultural (Cerdanyola del Vallès) | D10: UAB | E10: Cerdanyola del Vallès | F10: =+_xlfn.XLOOKUP(E10,Data_Cleaning!$B$6:$B$50,Data_Cleaning!$C$6:$C$50) -> Barcelona​ | G10: Social Sciences and Law | H10: =+_xlfn.XLOOKUP(G10,Data_Cleaning!$J$6:$J$11,Data_Cleaning!$K$6:$K$11) -> Social Sciences | I10: 5000 | J10: 5000 | K10: 6300 | L10: 5000
B11: 11029 | C11: Arqueologia (Barcelona) | D11: UB | E11: Barcelona | F11: =+_xlfn.XLOOKUP(E11,Data_Cleaning!$B$6:$B$50,Data_Cleaning!$C$6:$C$50) -> Barcelona​ | G11: Social Sciences and Law | H11: =+_xlfn.XLOOKUP(G11,Data_Cleaning!$J$6:$J$11,Data_Cleaning!$K$6:$K$11) -> Social Sciences | I11: 5000 | J11: 5000 | K11: 5000 | L11: 6833
B12: 21146 | C12: Arqueologia (Cerdanyola del Vallès) | D12: UAB | E12: Cerdanyola del Vallès | F12: =+_xlfn.XLOOKUP(E12,Data_Cleaning!$B$6:$B$50,Data_Cleaning!$C$6:$C$50) -> Barcelona​ | G12: Social Sciences and Law | H12: =+_xlfn.XLOOKUP(G12,Data_Cleaning!$J$6:$J$11,Data_Cleaning!$K$6:$K$11) -> Social Sciences | I12: 5000 | J12: 5000 | K12: 5000 | L12: 6667
B13: 81045 | C13: Arts Escèniques "ERAM" (Salt) | D13: UdG | E13: Salt | F13: =+_xlfn.XLOOKUP(E13,Data_Cleaning!$B$6:$B$50,Data_Cleaning!$C$6:$C$50) -> Girona​ | G13: {=_xlfn.XLOOKUP(TRUE,ISNUMBER(SEARCH(Data_Cleaning!$F$6:$F$36,C13)),Data_Cleaning!$G$6:$G$36,"Other",0)} -> Arts and Humanities | H13: =+_xlfn.XLOOKUP(G13,Data_Cleaning!$J$6:$J$11,Data_Cleaning!$K$6:$K$11) -> Arts and Humanities | I13: 5000 | J13: 5000 | K13: 5000 | L13: 5000
B14: 21020 | C14: Arts i Disseny "Massana" (Barcelona) | D14: UAB | E14: Barcelona | F14: =+_xlfn.XLOOKUP(E14,Data_Cleaning!$B$6:$B$50,Data_Cleaning!$C$6:$C$50) -> Barcelona​ | G14: {=_xlfn.XLOOKUP(TRUE,ISNUMBER(SEARCH(Data_Cleaning!$F$6:$F$36,C14)),Data_Cleaning!$G$6:$G$36,"Other",0)} -> Arts and Humanities | H14: =+_xlfn.XLOOKUP(G14,Data_Cleaning!$J$6:$J$11,Data_Cleaning!$K$6:$K$11) -> Arts and Humanities | I14: 5000 | J14: 5000 | K14: 5000 | L14: 5000
B15: 91063 | C15: Audiologia General (Vic) | D15: UVic-UCC | E15: Vic | F15: =+_xlfn.XLOOKUP(E15,Data_Cleaning!$B$6:$B$50,Data_Cleaning!$C$6:$C$50) -> Barcelona​ | G15: Health Sciences | H15: =+_xlfn.XLOOKUP(G15,Data_Cleaning!$J$6:$J$11,Data_Cleaning!$K$6:$K$11) -> Science and Technology | I15: 5000 | J15: 5000 | K15: 5000 | L15: 5000
B16: 91059 | C16: Belles Arts "BAU" (Barcelona) | D16: UVic-UCC | E16: Barcelona | F16: =+_xlfn.XLOOKUP(E16,Data_Cleaning!$B$6:$B$50,Data_Cleaning!$C$6:$C$50) -> Barcelona​ | G16: {=_xlfn.XLOOKUP(TRUE,ISNUMBER(SEARCH(Data_Cleaning!$F$6:$F$36,C16)),Data_Cleaning!$G$6:$G$36,"Other",0)} -> Arts and Humanities | H16: =+_xlfn.XLOOKUP(G16,Data_Cleaning!$J$6:$J$11,Data_Cleaning!$K$6:$K$11) -> Arts and Humanities | I16: 5000 | J16: 5000 | K16: 5000 | L16: 5000
B17: 11113 | C17: Ciències Culinàries i Gastronòmiques "CETT" (Barcelona) | D17: UB | E17: Barcelona | F17: =+_xlfn.XLOOKUP(E17,Data_Cleaning!$B$6:$B$50,Data_Cleaning!$C$6:$C$50) -> Barcelona​ | G17: Health Sciences | H17: =+_xlfn.XLOOKUP(G17,Data_Cleaning!$J$6:$J$11,Data_Cleaning!$K$6:$K$11) -> Science and Technology | I17: 5000 | J17: 5000 | K17: 5000 | L17: 5000
B18: 21117 | C18: Ciències de l'Antiguitat (Cerdanyola del Vallès) | D18: UAB | E18: Cerdanyola del Vallès | F18: =+_xlfn.XLOOKUP(E18,Data_Cleaning!$B$6:$B$50,Data_Cleaning!$C$6:$C$50) -> Barcelona​ | G18: Social Sciences and Law | H18: =+_xlfn.XLOOKUP(G18,Data_Cleaning!$J$6:$J$11,Data_Cleaning!$K$6:$K$11) -> Social Sciences | I18: 5000 | J18: 5000 | K18: 5000 | L18: 5000
B19: 11105 | C19: Cinematografia "ESCAC" (Terrassa) | D19: UB | E19: Terrassa | F19: =+_xlfn.XLOOKUP(E19,Data_Cleaning!$B$6:$B$50,Data_Cleaning!$C$6:$C$50) -> Barcelona​ | G19: Arts and Humanities | H19: =+_xlfn.XLOOKUP(G19,Data_Cleaning!$J$6:$J$11,Data_Cleaning!$K$6:$K$11) -> Arts and Humanities | I19: 5000 | J19: 5000 | K19: 5000 | L19: 5000
B20: 91006 | C20: Comunicació Audiovisual (Vic) | D20: UVic-UCC | E20: Vic | F20: =+_xlfn.XLOOKUP(E20,Data_Cleaning!$B$6:$B$50,Data_Cleaning!$C$6:$C$50) -> Barcelona​ | G20: {=_xlfn.XLOOKUP(TRUE,ISNUMBER(SEARCH(Data_Cleaning!$F$6:$F$36,C20)),Data_Cleaning!$G$6:$G$36,"Other",0)} -> Social Sciences and Law | H20: =+_xlfn.XLOOKUP(G20,Data_Cleaning!$J$6:$J$11,Data_Cleaning!$K$6:$K$11) -> Social Sciences | I20: 5000 | J20: 5000 | K20: 5000 | L20: 5000
B21: 81005 | C21: Comunicació Audiovisual i Multimèdia "ERAM" (Salt) | D21: UdG | E21: Salt | F21: =+_xlfn.XLOOKUP(E21,Data_Cleaning!$B$6:$B$50,Data_Cleaning!$C$6:$C$50) -> Girona​ | G21: {=_xlfn.XLOOKUP(TRUE,ISNUMBER(SEARCH(Data_Cleaning!$F$6:$F$36,C21)),Data_Cleaning!$G$6:$G$36,"Other",0)} -> Social Sciences and Law | H21: =+_xlfn.XLOOKUP(G21,Data_Cleaning!$J$6:$J$11,Data_Cleaning!$K$6:$K$11) -> Social Sciences | I21: 5000 | J21: 5000 | K21: 5000 | L21: 5000
B22: 81067 | C22: Comunicació Audiovisual i Multimèdia "ERAM" (docència en Anglès) (Salt) | D22: UdG | E22: Salt | F22: =+_xlfn.XLOOKUP(E22,Data_Cleaning!$B$6:$B$50,Data_Cleaning!$C$6:$C$50) -> Girona​ | G22: {=_xlfn.XLOOKUP(TRUE,ISNUMBER(SEARCH(Data_Cleaning!$F$6:$F$36,C22)),Data_Cleaning!$G$6:$G$36,"Other",0)} -> Social Sciences and Law | H22: =+_xlfn.XLOOKUP(G22,Data_Cleaning!$J$6:$J$11,Data_Cleaning!$K$6:$K$11) -> Social Sciences | I22: 5000 | J22: 5000 | K22: 5000 | L22: 5000
B23: 81068 | C23: Comunicació Cultural (Girona) | D23: UdG | E23: Girona | F23: =+_xlfn.XLOOKUP(E23,Data_Cleaning!$B$6:$B$50,Data_Cleaning!$C$6:$C$50) -> Girona​ | G23: {=_xlfn.XLOOKUP(TRUE,ISNUMBER(SEARCH(Data_Cleaning!$F$6:$F$36,C23)),Data_Cleaning!$G$6:$G$36,"Other",0)} -> Social Sciences and Law | H23: =+_xlfn.XLOOKUP(G23,Data_Cleaning!$J$6:$J$11,Data_Cleaning!$K$6:$K$11) -> Social Sciences | I23: 5000 | J23: 5000 | K23: 5000 | L23: 6667
B24: 61042 | C24: Conservació de la Natura / Enginyeria Forestal (simultaneïtat) (Lleida) | D24: UdL | E24: Lleida | F24: =+_xlfn.XLOOKUP(E24,Data_Cleaning!$B$6:$B$50,Data_Cleaning!$C$6:$C$50) -> Lleida​ | G24: {=_xlfn.XLOOKUP(TRUE,ISNUMBER(SEARCH(Data_Cleaning!$F$6:$F$36,C24)),Data_Cleaning!$G$6:$G$36,"Other",0)} -> Double Degree | H24: Social Sciences | I24: 5000 | J24: 5000 | K24: 7680 | L24: 5000
B25: 91050 | C25: Criminologia "ESERP" (Barcelona) | D25: UVic-UCC | E25: Barcelona | F25: =+_xlfn.XLOOKUP(E25,Data_Cleaning!$B$6:$B$50,Data_Cleaning!$C$6:$C$50) -> Barcelona​ | G25: Social Sciences and Law | H25: =+_xlfn.XLOOKUP(G25,Data_Cleaning!$J$6:$J$11,Data_Cleaning!$K$6:$K$11) -> Social Sciences | I25: 5000 | J25: 5000 | K25: 5000 | L25: 5000
B26: 81083 | C26: Direcció d'Empreses Hoteleres i Gastronòmiques (Sant Pol de Mar) | D26: UdG | E26: Sant Pol de Mar | F26: =+_xlfn.XLOOKUP(E26,Data_Cleaning!$B$6:$B$50,Data_Cleaning!$C$6:$C$50) -> Barcelona​ | G26: Social Sciences and Law | H26: =+_xlfn.XLOOKUP(G26,Data_Cleaning!$J$6:$J$11,Data_Cleaning!$K$6:$K$11) -> Social Sciences | I26: 5000 | J26: 5000 | K26: 5000 | L26: 5000
B27: 21107 | C27: Direcció Hotelera (Cerdanyola del Vallès) | D27: UAB | E27: Cerdanyola del Vallès | F27: =+_xlfn.XLOOKUP(E27,Data_Cleaning!$B$6:$B$50,Data_Cleaning!$C$6:$C$50) -> Barcelona​ | G27: Social Sciences and Law | H27: =+_xlfn.XLOOKUP(G27,Data_Cleaning!$J$6:$J$11,Data_Cleaning!$K$6:$K$11) -> Social Sciences | I27: 5000 | J27: 5000 | K27: 5000 | L27: 5000
B28: 11114 | C28: Direcció Hotelera Internacional "CETT" (Barcelona) | D28: UB | E28: Barcelona | F28: =+_xlfn.XLOOKUP(E28,Data_Cleaning!$B$6:$B$50,Data_Cleaning!$C$6:$C$50) -> Barcelona​ | G28: Social Sciences and Law | H28: =+_xlfn.XLOOKUP(G28,Data_Cleaning!$J$6:$J$11,Data_Cleaning!$K$6:$K$11) -> Social Sciences | I28: 5000 | J28: 5000 | K28: 5000 | L28: 5000
B29: 71085 | C29: Direcció i Gestió d'Empreses en l'Àmbit Digital "ESIC" (Barcelona) | D29: URV | E29: Barcelona | F29: =+_xlfn.XLOOKUP(E29,Data_Cleaning!$B$6:$B$50,Data_Cleaning!$C$6:$C$50) -> Barcelona​ | G29: Social Sciences and Law | H29: =+_xlfn.XLOOKUP(G29,Data_Cleaning!$J$6:$J$11,Data_Cleaning!$K$6:$K$11) -> Social Sciences | I29: 5000 | J29: 5000 | K29: 5000 | L29: 5000
B30: 11110 | C30: Direcció i Gestió Gastronòmica "Barcelona Culinary Hub" (L'Hospitalet de Llobregat) | D30: UB | E30: L'Hospitalet de Llobregat | F30: =+_xlfn.XLOOKUP(E30,Data_Cleaning!$B$6:$B$50,Data_Cleaning!$C$6:$C$50) -> Barcelona​ | G30: Social Sciences and Law | H30: =+_xlfn.XLOOKUP(G30,Data_Cleaning!$J$6:$J$11,Data_Cleaning!$K$6:$K$11) -> Social Sciences | I30: 5000 | J30: 5000 | K30: 5000 | L30: 5000
B31: 91007 | C31: Disseny "BAU" (Barcelona) | D31: UVic-UCC | E31: Barcelona | F31: =+_xlfn.XLOOKUP(E31,Data_Cleaning!$B$6:$B$50,Data_Cleaning!$C$6:$C$50) -> Barcelona​ | G31: Arts and Humanities | H31: =+_xlfn.XLOOKUP(G31,Data_Cleaning!$J$6:$J$11,Data_Cleaning!$K$6:$K$11) -> Arts and Humanities | I31: 5000 | J31: 5000 | K31: 5000 | L31: 5000
B32: 21015 | C32: Disseny "Eina" (Barcelona) | D32: UAB | E32: Barcelona | F32: =+_xlfn.XLOOKUP(E32,Data_Cleaning!$B$6:$B$50,Data_Cleaning!$C$6:$C$50) -> Barcelona​ | G32: Arts and Humanities | H32: =+_xlfn.XLOOKUP(G32,Data_Cleaning!$J$6:$J$11,Data_Cleaning!$K$6:$K$11) -> Arts and Humanities | I32: 5000 | J32: 5000 | K32: 5000 | L32: 5000
B33: 31121 | C33: Disseny Digital i Tecnologies Multimèdia (Terrassa) | D33: UPC | E33: Terrassa | F33: =+_xlfn.XLOOKUP(E33,Data_Cleaning!$B$6:$B$50,Data_Cleaning!$C$6:$C$50) -> Barcelona​ | G33: Arts and Humanities | H33: =+_xlfn.XLOOKUP(G33,Data_Cleaning!$J$6:$J$11,Data_Cleaning!$K$6:$K$11) -> Arts and Humanities | I33: 5000 | J33: 5000 | K33: 5000 | L33: 5000
B34: 31083 | C34: Disseny i Desenvolupament de Videojocs (docència en Anglès) (Campus Barcelona) (Barcelona / Terrassa) | D34: UPC | E34: Barcelona / Terrassa | F34: =+_xlfn.XLOOKUP(E34,Data_Cleaning!$B$6:$B$50,Data_Cleaning!$C$6:$C$50) -> Barcelona​ | G34: Engineering and Architecture | H34: =+_xlfn.XLOOKUP(G34,Data_Cleaning!$J$6:$J$11,Data_Cleaning!$K$6:$K$11) -> Science and Technology | I34: 5000 | J34: 6750 | K34: 5000 | L34: 5000
B35: 31074 | C35: Disseny i Desenvolupament de Videojocs (Campus Terrassa) (Barcelona / Terrassa) | D35: UPC | E35: Barcelona / Terrassa | F35: =+_xlfn.XLOOKUP(E35,Data_Cleaning!$B$6:$B$50,Data_Cleaning!$C$6:$C$50) -> Barcelona​ | G35: Engineering and Architecture | H35: =+_xlfn.XLOOKUP(G35,Data_Cleaning!$J$6:$J$11,Data_Cleaning!$K$6:$K$11) -> Science and Technology | I35: 5000 | J35: 5000 | K35: 5000 | L35: 5000
B36: 11106 | C36: Disseny i Desenvolupament de Videojocs i Jocs Aplicats "ENTI" (Barcelona) | D36: UB | E36: Barcelona | F36: =+_xlfn.XLOOKUP(E36,Data_Cleaning!$B$6:$B$50,Data_Cleaning!$C$6:$C$50) -> Barcelona​ | G36: Engineering and Architecture | H36: =+_xlfn.XLOOKUP(G36,Data_Cleaning!$J$6:$J$11,Data_Cleaning!$K$6:$K$11) -> Science and Technology | I36: 5000 | J36: 5000 | K36: 5000 | L36: 5000
... B38: 41045 | C38: Disseny i Producció de Videojocs "Tecnocampus" (Mataró) | D38: UPF | E38: Mataró | F38: =+_xlfn.XLOOKUP(E38,Data_Cleaning!$B$6:$B$50,Data_Cleaning!$C$6:$C$50) -> Barcelona​ | G38: Engineering and Architecture | H38: =+_xlfn.XLOOKUP(G38,Data_Cleaning!$J$6:$J$11,Data_Cleaning!$K$6:$K$11) -> Science and Technology | I38: 5000 | J38: 5000 | K38: 5000 | L38: 5000
B39: 41052 | C39: Disseny i Producció de Videojocs / Enginyeria Informàtica de Gestió i Sistemes d'Informació "Tecnocampus" (simultaneïtat) (Mataró) | D39: UPF | E39: Mataró | F39: =+_xlfn.XLOOKUP(E39,Data_Cleaning!$B$6:$B$50,Data_Cleaning!$C$6:$C$50) -> Barcelona​ | G39: {=_xlfn.XLOOKUP(TRUE,ISNUMBER(SEARCH(Data_Cleaning!$F$6:$F$36,C39)),Data_Cleaning!$G$6:$G$36,"Other",0)} -> Double Degree | H39: Science and Technology | I39: 5000 | J39: 5000 | K39: 5000 | L39: 5000
B40: 91921 | C40: Disseny per als Sistemes Alimentaris "ELISAVA-CETT" (Barcelona) | D40: UVic-UCC / UB | E40: Barcelona | F40: =+_xlfn.XLOOKUP(E40,Data_Cleaning!$B$6:$B$50,Data_Cleaning!$C$6:$C$50) -> Barcelona​ | G40: Health Sciences | H40: =+_xlfn.XLOOKUP(G40,Data_Cleaning!$J$6:$J$11,Data_Cleaning!$K$6:$K$11) -> Science and Technology | I40: 5000 | J40: 5000 | K40: 5000 | L40: 5000
B41: 91053 | C41: Dret "ESERP" (Barcelona) | D41: UVic-UCC | E41: Barcelona | F41: =+_xlfn.XLOOKUP(E41,Data_Cleaning!$B$6:$B$50,Data_Cleaning!$C$6:$C$50) -> Barcelona​ | G41: {=_xlfn.XLOOKUP(TRUE,ISNUMBER(SEARCH(Data_Cleaning!$F$6:$F$36,C41)),Data_Cleaning!$G$6:$G$36,"Other",0)} -> Social Sciences and Law | H41: =+_xlfn.XLOOKUP(G41,Data_Cleaning!$J$6:$J$11,Data_Cleaning!$K$6:$K$11) -> Social Sciences | I41: 5000 | J41: 5000 | K41: 5000 | L41: 5000
B42: 61011 | C42: Educació Infantil (Lleida) | D42: UdL | E42: Lleida | F42: =+_xlfn.XLOOKUP(E42,Data_Cleaning!$B$6:$B$50,Data_Cleaning!$C$6:$C$50) -> Lleida​ | G42: {=_xlfn.XLOOKUP(TRUE,ISNUMBER(SEARCH(Data_Cleaning!$F$6:$F$36,C42)),Data_Cleaning!$G$6:$G$36,"Other",0)} -> Social Sciences and Law | H42: =+_xlfn.XLOOKUP(G42,Data_Cleaning!$J$6:$J$11,Data_Cleaning!$K$6:$K$11) -> Social Sciences | I42: 5000 | J42: 5000 | K42: 5000 | L42: 5000
...

Sheet Data_Cleaning
B5: Unique Regions from Table 1 - Column E | C5: Province | F5: Keyword | G5: Field | J5: Batxillerat | K5: Batxillerat
B6: Mataró | C6: Barcelona​ | F6: (simultaneïtat) | G6: Double Degree | J6: Double Degree | K6: Manual
B7: Barcelona | C7: Barcelona​ | F7: Treball | G7: Social Sciences and Law | J7: Social Sciences and Law | K7: Social Sciences
B8: Cerdanyola del Vallès | C8: Barcelona​ | F8: Enginyeria | G8: Engineering and Architecture | J8: Engineering and Architecture | K8: Science and Technology
B9: Girona | C9: Girona​ | F9: Arquitectura | G9: Engineering and Architecture | J9: Sciences | K9: Science and Technology
B10: Igualada | C10: Barcelona​ | F10: Química | G10: Sciences | J10: Health Sciences | K10: Science and Technology
B11: Lleida | C11: Lleida​ | F11: Biologia | G11: Sciences | J11: Arts and Humanities | K11: Arts and Humanities
B12: Manresa | C12: Barcelona​ | F12: Ciències Ambientals | G12: Sciences
B13: Reus | C13: Tarragona​ | F13: Matemàtiques | G13: Sciences
B14: Tortosa | C14: Tarragona​ | F14: Física | G14: Sciences
B15: Vic | C15: Barcelona​ | F15: Empresa | G15: Social Sciences and Law
B16: Tarragona / Reus | C16: Tarragona​ | F16: Administració | G16: Social Sciences and Law
B17: Reus / Barcelona | C17: Tarragona​ | F17: Economia | G17: Social Sciences and Law
B18: Tortosa / Barcelona | C18: Tarragona​ | F18: Dret | G18: Social Sciences and Law
B19: Tarragona | C19: Tarragona​ | F19: Turisme | G19: Social Sciences and Law
B20: Sant Cugat del Vallès | C20: Barcelona​ | F20: Psicologia | G20: Health Sciences
B21: Salt | C21: Girona​ | F21: Medicina | G21: Health Sciences
B22: Barcelona / Cerdanyola del Vallès | C22: Barcelona​ | F22: Infermeria | G22: Health Sciences
B23: Santa Coloma de Gramenet | C23: Barcelona​ | F23: Fisioteràpia | G23: Health Sciences
... B38: Manresa / Barcelona | C38: Barcelona​ | F38: Traducció | G38: Arts and Humanities
B39: Vilanova i la Geltrú | C39: Barcelona​
B40: Granollers | C40: Barcelona​
B41: Barcelona / Santa Coloma de Gramenet | C41: Barcelona​
B42: Cerdanyola del Vallès / Barcelona | C42: Barcelona​
B43: Vila-Seca | C43: Tarragona​
B44: Sant Boi de Llobregat | C44: Barcelona​
B45: Tremp | C45: Lleida​
B46: Vilafranca del Penedès / el Vendrell | C46: Barcelona​
B47: Girona / Salt | C47: Girona​
B48: Manresa / Vic | C48: Barcelona​
B49: Barcelona / Castelldefels | C49: Barcelona​
B50: Mollet del Vallès | C50: Barcelona​

Sheet Back-up >>>
B3: Back-up >>>

Sheet Table 1_Raw
B2: Notes de tall 1a assignació Juny 2025 (11/07/25)
B3: Ordre alfabètic per centre d'estudi
B4: ESTUDIS DE GRAU I TÍTOLS PROPIS
B5: Codi | D5: Nom del centre d'estudi i població | G5: Sigles Universitat | I5: PAU / CFGS | K5: Més grans de 25 anys | M5: Titulats universitaris | O5: Més grans de 45 anys
B6: 41029 | D6: Administració d'Empreses i Gestió de la Innovació "Tecnocampus" (Mataró) | G6: UPF | I6: 7688 | K6: 5000 | M6: 5000 | O6: 5000
B7: 41036 | D7: Administració d'Empreses i Gestió de la Innovació "Tecnocampus" (docència en Anglès) (Mataró) | G7: UPF | I7: 7628 | K7: 5000 | M7: 5000 | O7: 5000
B8: 41041 | D8: Administració d'Empreses i Gestió de la Innovació / Màrqueting i Comunitats Digitals "Tecnocampus" (simultaneïtat) (Mataró) | G8: UPF | I8: 7546 | K8: 5000 | M8: 5000 | O8: 5000
B9: 41035 | D9: Administració d'Empreses i Gestió de la Innovació / Turisme i Gestió del Lleure "Tecnocampus" (simultaneïtat) (Mataró) | G9: UPF | I9: 5000 | K9: 5000 | M9: 5000 | O9: 5000
B10: 11033 | D10: Administració i Direcció d'Empreses (Barcelona) | G10: UB | I10: 9348 | K10: 5000 | M10: 5000 | O10: 5000
B11: 41008 | D11: Administració i Direcció d'Empreses (Barcelona) | G11: UPF | I11: 10966 | K11: 5000 | M11: 5000 | O11: 5000
B12: 71063 | D12: Administració i Direcció d'Empreses "IGEMA" (Barcelona) | G12: URV | I12: 5000 | K12: 5000 | M12: 5000 | O12: 5000
B13: 21014 | D13: Administració i Direcció d'Empreses (Cerdanyola del Vallès) | G13: UAB | I13: 9804 | K13: 5000 | M13: 5000 | O13: 5000
B14: 21099 | D14: Administració i Direcció d'Empreses (docència en Anglès) (Cerdanyola del Vallès) | G14: UAB | I14: 10128 | K14: 5000 | M14: 5000 | O14: 5000
B15: 81003 | D15: Administració i Direcció d'Empreses (Girona) | G15: UdG | I15: 9218 | K15: 5000 | M15: 5000 | O15: 6333
B16: 61069 | D16: Administració i Direcció d'Empreses (Igualada) | G16: UdL | I16: 8224 | K16: 5000 | M16: 5000 | O16: 5000
B17: 61003 | D17: Administració i Direcció d'Empreses (Lleida) | G17: UdL | I17: 7764 | K17: 5000 | M17: 5000 | O17: 5000
... B71: 71054 | D71: Bioquímica i Biologia Molecular / Biotecnologia (simultaneïtat) (Tarragona) | G71: URV | I71: 12280 | K71: 5000 | M71: 9130 | O71: 5000
A73: Codi | C73: Nom del centre d'estudi i població | F73: Sigles Universitat | H73: PAU / CFGS | J73: Més grans de 25 anys | L73: Titulats universitaris | N73: Més grans de 45 anys
A74: 11004 | C74: Biotecnologia (Barcelona) | F74: UB | H74: 11830 | J74: 5000 | L74: 6510 | N74: 5000
A75: 21012 | C75: Biotecnologia (Cerdanyola del Vallès) | F75: UAB | H75: 11506 | J75: 5000 | L75: 5000 | N75: 5000
A76: 81007 | C76: Biotecnologia (Girona) | F76: UdG | H76: 10354 | J76: 5000 | L76: 5000 | N76: 5000
A77: 61005 | C77: Biotecnologia (Lleida) | F77: UdL | H77: 10196 | J77: 5000 | L77: 5000 | N77: 5000
A78: 71006 | C78: Biotecnologia (Tarragona) | F78: URV | H78: 10816 | J78: 5000 | L78: 5000 | N78: 5000
A79: 91004 | C79: Biotecnologia (Vic) | F79: UVic-UCC | H79: 7432 | J79: 5000 | L79: 5000 | N79: 5000
A80: 71056 | C80: Biotecnologia / Enginyeria Informàtica (simultaneïtat) (Tarragona) | F80: URV | H80: 10224 | J80: 5000 | L80: 5000 | N80: 5000
A81: 11109 | C81: Ciberseguretat "ENTI" (Barcelona) | F81: UB | H81: 8299 | J81: 5000 | L81: 5000 | N81: 5000
A82: 31089 | C82: Ciència i Enginyeria de Dades (Barcelona) | F82: UPC | H82: 12514 | J82: 5000 | L82: 6610 | N82: 5000
A83: 61040 | C83: Ciència i Producció Animal / Veterinària (simultaneïtat) (Lleida) | F83: UdL | H83: 11329 | J83: 7000 | L83: 7800 | N83: 5000
A84: 21021 | C84: Ciència i Tecnologia dels Aliments (Cerdanyola del Vallès) | F84: UAB | H84: 9032 | J84: 5000 | L84: 5000 | N84: 5833
A85: 61008 | C85: Ciència i Tecnologia dels Aliments (Lleida) | F85: UdL | H85: 5770 | J85: 5000 | L85: 5000 | N85: 5000
... A152: 71085 | C152: Direcció i Gestió d'Empreses en l'Àmbit Digital "ESIC" (Barcelona) | F152: URV | H152: 5000 | J152: 5000 | L152: 5000 | N152: 5000
A153: Codi | C153: Nom del centre d'estudi i població | F153: Sigles Universitat | H153: PAU / CFGS | J153: Més grans de 25 anys | L153: Titulats universitaris | N153: Més grans de 45 anys
A154: 11110 | C154: Direcció i Gestió Gastronòmica "Barcelona Culinary Hub" (L'Hospitalet de Llobregat) | F154: UB | H154: 5000 | J154: 5000 | L154: 5000 | N154: 5000
A155: 11101 | C155: Disseny (Barcelona) | F155: UB | H155: 10700 | J155: 8125 | L155: 5000 | N155: 7167
A156: 91007 | C156: Disseny "BAU" (Barcelona) | F156: UVic-UCC | H156: 5000 | J156: 5000 | L156: 5000 | N156: 5000
A157: 21015 | C157: Disseny "Eina" (Barcelona) | F157: UAB | H157: 5000 | J157: 5000 | L157: 5000 | N157: 5000
A158: 61064 | C158: Disseny Digital i Tecnologies Creatives (Lleida) | F158: UdL | H158: 8398 | J158: 5000 | L158: 5000 | N158: 5000
A159: 31121 | C159: Disseny Digital i Tecnologies Multimèdia (Terrassa) | F159: UPC | H159: 5000 | J159: 5000 | L159: 5000 | N159: 5000
A160: 31083 | C160: Disseny i Desenvolupament de Videojocs (docència en Anglès) (Campus Barcelona) (Barcelona / Terrassa) | F160: UPC | H160: 5000 | J160: 6750 | L160: 5000 | N160: 5000
A161: 81059 | C161: Disseny i Desenvolupament de Videojocs (Girona) | F161: UdG | H161: 7408 | J161: 5000 | L161: 5000 | N161: 5000
...
